<?xml version="1.0" ?>
<robot name="Apartment" version="1.0">
  <link name="Apartment"/>
  <joint name="Root_joint" type="fixed">
    <origin xyz="0.0 0.0 0.0" rpy="0.0 0.0 0.0"/>
    <parent link="Apartment"/>
    <child link="Root"/>
  </joint>
  <link name="Root">
    <inertial>
      <origin xyz="0.0 0.0 0.0" rpy="0.0 0.0 0.0"/>
      <mass value="0.0"/>
      <inertia ixx="0.0" ixy="0.0" ixz="0.0" iyy="0.0" iyz="0.0" izz="0.0"/>
    </inertial>
  </link>
  <joint name="SM_Kitchen_01_Base_joint" type="fixed">
    <origin xyz="9.167593955993652 -4.039442539215088 1.0418363809585571" rpy="0.0 0.0 -1.5707899332046509"/>
    <parent link="Root"/>
    <child link="SM_Kitchen_01_Base"/>
  </joint>
  <link name="SM_Kitchen_01_Base">
    <inertial>
      <origin xyz="0.009944741614162922 0.039557792246341705 0.21815285086631775" rpy="-3.300314347143285e-05 -0.014300175942480564 1.5857877731323242"/>
      <mass value="152.33148193359375"/>
      <inertia ixx="81.37260437011719" ixy="0.0" ixz="0.0" iyy="76.05228424072266" iyz="0.0" izz="14.473698616027832"/>
    </inertial>
  </link>
  <joint name="SM_Kitchen_01_Door_01_joint" type="revolute">
    <origin xyz="8.887999534606934 -3.7652812004089355 1.7192974090576172" rpy="0.0 0.0 -1.5707920789718628"/>
    <axis xyz="0.0 0.0 -1.0"/>
    <parent link="Root"/>
    <child link="SM_Kitchen_01_Door_01"/>
    <limit effort="1000.0" lower="0.0" upper="1.5707963705062866" velocity="1000.0"/>
  </joint>
  <link name="SM_Kitchen_01_Door_01">
    <inertial>
      <origin xyz="0.28759047389030457 -0.0006468892097473145 -1.1175870895385742e-07" rpy="0.0 0.0 1.5707963705062866"/>
      <mass value="9.747746467590332"/>
      <inertia ixx="0.8949631452560425" ixy="0.0" ixz="0.0" iyy="0.610632061958313" iyz="0.0" izz="0.2849174439907074"/>
    </inertial>
  </link>
  <joint name="SM_Kitchen_Handle4_joint" type="fixed">
    <origin xyz="0.4631551504135132 -0.01559523493051529 -0.38983428478240967" rpy="0.0 0.0 1.5707995891571045"/>
    <parent link="SM_Kitchen_01_Door_01"/>
    <child link="SM_Kitchen_Handle4"/>
  </joint>
  <link name="SM_Kitchen_Handle4">
    <inertial>
      <origin xyz="-0.01734265126287937 -4.472618456929922e-06 0.0004545578849501908" rpy="1.5707920789718628 -1.5707963705062866 0.0"/>
      <mass value="0.033401232212781906"/>
      <inertia ixx="0.00010963201930280775" ixy="0.0" ixz="0.0" iyy="0.00010809655941557139" iyz="0.0" izz="2.349011538171908e-06"/>
    </inertial>
  </link>
  <joint name="SM_Kitchen_01_Drawer_01_joint" type="prismatic">
    <origin xyz="9.120807647705078 -4.050665378570557 0.5552511215209961" rpy="0.0 0.0 -1.5707920789718628"/>
    <axis xyz="0.0 -1.0 0.0"/>
    <parent link="Root"/>
    <child link="SM_Kitchen_01_Drawer_01"/>
    <limit effort="1000.0" lower="0.0" upper="0.4000000059604645" velocity="1000.0"/>
  </joint>
  <link name="SM_Kitchen_01_Drawer_01">
    <inertial>
      <origin xyz="-1.3268040000014025e-09 -0.025337589904665947 -0.0437018945813179" rpy="0.0 -1.4715920686721802 1.5707963705062866"/>
      <mass value="8.477095603942871"/>
      <inertia ixx="0.6637729406356812" ixy="0.0" ixz="0.0" iyy="0.38019412755966187" iyz="0.0" izz="0.355472594499588"/>
    </inertial>
  </link>
  <joint name="SM_Kitchen_Handle2_joint" type="fixed">
    <origin xyz="0.0009132502018474042 -0.24792969226837158 0.08401428163051605" rpy="0.0 0.0 1.5707995891571045"/>
    <parent link="SM_Kitchen_01_Drawer_01"/>
    <child link="SM_Kitchen_Handle2"/>
  </joint>
  <link name="SM_Kitchen_Handle2">
    <inertial>
      <origin xyz="-0.01734265126287937 -4.472618456929922e-06 0.0004545578849501908" rpy="1.5707920789718628 -1.5707963705062866 0.0"/>
      <mass value="0.033401232212781906"/>
      <inertia ixx="0.00010963201930280775" ixy="0.0" ixz="0.0" iyy="0.00010809655941557139" iyz="0.0" izz="2.349011538171908e-06"/>
    </inertial>
  </link>
  <joint name="SM_Counter_Sink_joint" type="fixed">
    <origin xyz="6.988356590270996 -5.947266578674316 0.7754639983177185" rpy="0.0 0.0 1.570798397064209"/>
    <parent link="Root"/>
    <child link="SM_Counter_Sink"/>
  </joint>
  <link name="SM_Counter_Sink">
    <inertial>
      <origin xyz="-5.864903562802226e-10 0.04239964485168457 -0.011014905758202076" rpy="3.1415927410125732 -1.4915213584899902 -1.5707963705062866"/>
      <mass value="11.287463188171387"/>
      <inertia ixx="0.4650149941444397" ixy="0.0" ixz="0.0" iyy="0.2909996211528778" iyz="0.0" izz="0.23556441068649292"/>
    </inertial>
  </link>
  <joint name="SM_Kitchen_10_Drawer_02_joint" type="prismatic">
    <origin xyz="7.009951114654541 -4.844547271728516 0.556601881980896" rpy="0.0 0.0 1.570798397064209"/>
    <axis xyz="0.0 -1.0 0.0"/>
    <parent link="Root"/>
    <child link="SM_Kitchen_10_Drawer_02"/>
    <limit effort="1000.0" lower="0.0" upper="0.4000000059604645" velocity="1000.0"/>
  </joint>
  <link name="SM_Kitchen_10_Drawer_02">
    <inertial>
      <origin xyz="-7.82054476733407e-10 -0.023389536887407303 -0.04450542479753494" rpy="0.0 -1.4745656251907349 1.5707963705062866"/>
      <mass value="6.215494155883789"/>
      <inertia ixx="0.34396618604660034" ixy="0.0" ixz="0.0" iyy="0.2639531195163727" iyz="0.0" izz="0.13102813065052032"/>
    </inertial>
  </link>
  <joint name="SM_Kitchen_Handle19_joint" type="fixed">
    <origin xyz="0.002975543960928917 -0.2488568127155304 0.08705490082502365" rpy="0.0 0.0 1.5708003044128418"/>
    <parent link="SM_Kitchen_10_Drawer_02"/>
    <child link="SM_Kitchen_Handle19"/>
  </joint>
  <link name="SM_Kitchen_Handle19">
    <inertial>
      <origin xyz="-0.01734265126287937 -4.472618456929922e-06 0.0004545578849501908" rpy="1.5707920789718628 -1.5707963705062866 0.0"/>
      <mass value="0.033401232212781906"/>
      <inertia ixx="0.00010963201930280775" ixy="0.0" ixz="0.0" iyy="0.00010809655941557139" iyz="0.0" izz="2.349011538171908e-06"/>
    </inertial>
  </link>
  <joint name="SM_Kitchen_11_Base_Drawer_01_joint" type="prismatic">
    <origin xyz="7.010114669799805 -4.194895267486572 0.7554433941841125" rpy="0.0 0.0 1.570798397064209"/>
    <axis xyz="0.0 -1.0 0.0"/>
    <parent link="Root"/>
    <child link="SM_Kitchen_11_Base_Drawer_01"/>
    <limit effort="1000.0" lower="0.0" upper="0.4000000059604645" velocity="1000.0"/>
  </joint>
  <link name="SM_Kitchen_11_Base_Drawer_01">
    <inertial>
      <origin xyz="-5.869753572085301e-10 -0.01646357774734497 -0.0178831797093153" rpy="1.5707963705062866 -1.5413669347763062 1.5707963705062866"/>
      <mass value="8.016010284423828"/>
      <inertia ixx="0.9731644988059998" ixy="0.0" ixz="0.0" iyy="0.6888277530670166" iyz="0.0" izz="0.2966335117816925"/>
    </inertial>
  </link>
  <joint name="SM_Kitchen_Handle21_joint" type="fixed">
    <origin xyz="0.01083565317094326 -0.24797548353672028 0.0203857421875" rpy="0.0 0.0 1.5708003044128418"/>
    <parent link="SM_Kitchen_11_Base_Drawer_01"/>
    <child link="SM_Kitchen_Handle21"/>
  </joint>
  <link name="SM_Kitchen_Handle21">
    <inertial>
      <origin xyz="-0.01734265126287937 -4.472618456929922e-06 0.0004545578849501908" rpy="1.5707920789718628 -1.5707963705062866 0.0"/>
      <mass value="0.033401232212781906"/>
      <inertia ixx="0.00010963201930280775" ixy="0.0" ixz="0.0" iyy="0.00010809655941557139" iyz="0.0" izz="2.349011538171908e-06"/>
    </inertial>
  </link>
  <joint name="SM_Kitchen_11_Base_Drawer_02_joint" type="prismatic">
    <origin xyz="7.009596824645996 -4.194708347320557 0.5564532279968262" rpy="0.0 0.0 1.570798397064209"/>
    <axis xyz="0.0 -1.0 0.0"/>
    <parent link="Root"/>
    <child link="SM_Kitchen_11_Base_Drawer_02"/>
    <limit effort="1000.0" lower="0.0" upper="0.4000000059604645" velocity="1000.0"/>
  </joint>
  <link name="SM_Kitchen_11_Base_Drawer_02">
    <inertial>
      <origin xyz="-1.5591179458596116e-09 -0.026966622099280357 -0.043613698333501816" rpy="1.5707963705062866 -1.4705300331115723 1.5707963705062866"/>
      <mass value="11.90747356414795"/>
      <inertia ixx="1.479491949081421" ixy="0.0" ixz="0.0" iyy="1.0266789197921753" iyz="0.0" izz="0.5566962957382202"/>
    </inertial>
  </link>
  <joint name="SM_Kitchen_Handle22_joint" type="fixed">
    <origin xyz="0.010648884810507298 -0.24849306046962738 0.08720351755619049" rpy="0.0 0.0 1.5708003044128418"/>
    <parent link="SM_Kitchen_11_Base_Drawer_02"/>
    <child link="SM_Kitchen_Handle22"/>
  </joint>
  <link name="SM_Kitchen_Handle22">
    <inertial>
      <origin xyz="-0.01734265126287937 -4.472618456929922e-06 0.0004545578849501908" rpy="1.5707920789718628 -1.5707963705062866 0.0"/>
      <mass value="0.033401232212781906"/>
      <inertia ixx="0.00010963201930280775" ixy="0.0" ixz="0.0" iyy="0.00010809655941557139" iyz="0.0" izz="2.349011538171908e-06"/>
    </inertial>
  </link>
  <joint name="SM_Kitchen_06_Base_Drawer_01_joint" type="prismatic">
    <origin xyz="9.124244689941406 -6.156850337982178 0.7529809474945068" rpy="0.0 0.0 -1.5707920789718628"/>
    <axis xyz="0.0 -1.0 0.0"/>
    <parent link="Root"/>
    <child link="SM_Kitchen_06_Base_Drawer_01"/>
    <limit effort="1000.0" lower="0.0" upper="0.4000000059604645" velocity="1000.0"/>
  </joint>
  <link name="SM_Kitchen_06_Base_Drawer_01">
    <inertial>
      <origin xyz="1.0153192731010563e-09 -0.01303133275359869 -0.01641898788511753" rpy="0.0 -1.545478105545044 1.5707963705062866"/>
      <mass value="4.332450866699219"/>
      <inertia ixx="0.21865983307361603" ixy="0.0" ixz="0.0" iyy="0.1454179883003235" iyz="0.0" izz="0.07959701120853424"/>
    </inertial>
  </link>
  <joint name="SM_Kitchen_Handle9_joint" type="fixed">
    <origin xyz="0.001248949090950191 -0.24662108719348907 0.01720382645726204" rpy="0.0 0.0 1.5707995891571045"/>
    <parent link="SM_Kitchen_06_Base_Drawer_01"/>
    <child link="SM_Kitchen_Handle9"/>
  </joint>
  <link name="SM_Kitchen_Handle9">
    <inertial>
      <origin xyz="-0.01734265126287937 -4.472618456929922e-06 0.0004545578849501908" rpy="1.5707920789718628 -1.5707963705062866 0.0"/>
      <mass value="0.033401232212781906"/>
      <inertia ixx="0.00010963201930280775" ixy="0.0" ixz="0.0" iyy="0.00010809655941557139" iyz="0.0" izz="2.349011538171908e-06"/>
    </inertial>
  </link>
  <joint name="SM_Counter_Wall_joint" type="fixed">
    <origin xyz="9.17080020904541 -5.867626667022705 0.8363512754440308" rpy="0.0 0.0 1.5708009004592896"/>
    <parent link="Root"/>
    <child link="SM_Counter_Wall"/>
  </joint>
  <link name="SM_Counter_Wall">
    <inertial>
      <origin xyz="-0.001177995465695858 -1.4901161193847656e-08 0.00041857175529003143" rpy="3.1415927410125732 -1.570796251296997 0.0"/>
      <mass value="17.817127227783203"/>
      <inertia ixx="2.1089749336242676" ixy="0.0" ixz="0.0" iyy="1.575695514678955" iyz="0.0" izz="0.5357487797737122"/>
    </inertial>
  </link>
  <joint name="SM_Kitchen_Island_Cover_03_joint" type="fixed">
    <origin xyz="6.913930416107178 -6.849991321563721 0.37919020652770996" rpy="0.0 0.0 -1.5707899332046509"/>
    <parent link="Root"/>
    <child link="SM_Kitchen_Island_Cover_03"/>
  </joint>
  <link name="SM_Kitchen_Island_Cover_03">
    <inertial>
      <origin xyz="5.513429641723633e-07 5.960464477539063e-08 1.4156103134155273e-07" rpy="0.0 0.0 0.0"/>
      <mass value="12.20611572265625"/>
      <inertia ixx="1.2901133298873901" ixy="0.0" ixz="0.0" iyy="0.820485532283783" iyz="0.0" izz="0.47044143080711365"/>
    </inertial>
  </link>
  <joint name="SM_Counter_Sink_Stove_joint" type="fixed">
    <origin xyz="6.799489498138428 -5.281734466552734 0.39305952191352844" rpy="0.0 0.0 1.570798397064209"/>
    <parent link="Root"/>
    <child link="SM_Counter_Sink_Stove"/>
  </joint>
  <link name="SM_Counter_Sink_Stove">
    <inertial>
      <origin xyz="0.3828611969947815 0.00811659637838602 0.348103791475296" rpy="3.1002445220947266 -1.4506502151489258 0.03343126177787781"/>
      <mass value="116.8432388305664"/>
      <inertia ixx="138.10971069335938" ixy="0.0" ixz="0.0" iyy="132.72544860839844" iyz="0.0" izz="14.414215087890625"/>
    </inertial>
  </link>
  <joint name="SM_Kitchen_Island_Cover_5_joint" type="fixed">
    <origin xyz="6.91473388671875 -3.7335832118988037 0.3734439015388489" rpy="0.0 0.0 -1.5707899332046509"/>
    <parent link="Root"/>
    <child link="SM_Kitchen_Island_Cover_5"/>
  </joint>
  <link name="SM_Kitchen_Island_Cover_5">
    <inertial>
      <origin xyz="5.513429641723633e-07 5.960464477539063e-08 1.4156103134155273e-07" rpy="0.0 0.0 0.0"/>
      <mass value="12.20611572265625"/>
      <inertia ixx="1.2901133298873901" ixy="0.0" ixz="0.0" iyy="0.820485532283783" iyz="0.0" izz="0.47044143080711365"/>
    </inertial>
  </link>
  <joint name="SM_Kitchen_05_Base_Drawer_03_joint" type="prismatic">
    <origin xyz="9.124014854431152 -5.657559871673584 0.22597000002861023" rpy="0.0 0.0 -1.5707920789718628"/>
    <axis xyz="0.0 -1.0 0.0"/>
    <parent link="Root"/>
    <child link="SM_Kitchen_05_Base_Drawer_03"/>
    <limit effort="1000.0" lower="0.0" upper="0.4000000059604645" velocity="1000.0"/>
  </joint>
  <link name="SM_Kitchen_05_Base_Drawer_03">
    <inertial>
      <origin xyz="-2.5427215888385035e-09 -0.0572405681014061 -0.06563190370798111" rpy="0.0 -1.3127354383468628 1.5707963705062866"/>
      <mass value="10.007306098937988"/>
      <inertia ixx="0.784437358379364" ixy="0.0" ixz="0.0" iyy="0.5045651197433472" iyz="0.0" izz="0.4500564634799957"/>
    </inertial>
  </link>
  <joint name="SM_Kitchen_Handle11_joint" type="fixed">
    <origin xyz="-0.001032554660923779 -0.24888183176517487 0.15027038753032684" rpy="0.0 0.0 1.5707995891571045"/>
    <parent link="SM_Kitchen_05_Base_Drawer_03"/>
    <child link="SM_Kitchen_Handle11"/>
  </joint>
  <link name="SM_Kitchen_Handle11">
    <inertial>
      <origin xyz="-0.01734265126287937 -4.472618456929922e-06 0.0004545578849501908" rpy="1.5707920789718628 -1.5707963705062866 0.0"/>
      <mass value="0.033401232212781906"/>
      <inertia ixx="0.00010963201930280775" ixy="0.0" ixz="0.0" iyy="0.00010809655941557139" iyz="0.0" izz="2.349011538171908e-06"/>
    </inertial>
  </link>
  <joint name="SM_Kitchen_01_Drawer_02_joint" type="prismatic">
    <origin xyz="9.121969223022461 -4.050127029418945 0.22633399069309235" rpy="0.0 0.0 -1.5707920789718628"/>
    <axis xyz="0.0 -1.0 0.0"/>
    <parent link="Root"/>
    <child link="SM_Kitchen_01_Drawer_02"/>
    <limit effort="1000.0" lower="0.0" upper="0.4000000059604645" velocity="1000.0"/>
  </joint>
  <link name="SM_Kitchen_01_Drawer_02">
    <inertial>
      <origin xyz="-2.5427215888385035e-09 -0.0572405681014061 -0.06563190370798111" rpy="0.0 -1.3127354383468628 1.5707963705062866"/>
      <mass value="10.007306098937988"/>
      <inertia ixx="0.784437358379364" ixy="0.0" ixz="0.0" iyy="0.5045651197433472" iyz="0.0" izz="0.4500564634799957"/>
    </inertial>
  </link>
  <joint name="SM_Kitchen_Handle3_joint" type="fixed">
    <origin xyz="0.001451575313694775 -0.24909180402755737 0.15060600638389587" rpy="0.0 0.0 1.5707995891571045"/>
    <parent link="SM_Kitchen_01_Drawer_02"/>
    <child link="SM_Kitchen_Handle3"/>
  </joint>
  <link name="SM_Kitchen_Handle3">
    <inertial>
      <origin xyz="-0.01734265126287937 -4.472618456929922e-06 0.0004545578849501908" rpy="1.5707920789718628 -1.5707963705062866 0.0"/>
      <mass value="0.033401232212781906"/>
      <inertia ixx="0.00010963201930280775" ixy="0.0" ixz="0.0" iyy="0.00010809655941557139" iyz="0.0" izz="2.349011538171908e-06"/>
    </inertial>
  </link>
  <joint name="SM_Dishwasher_Base_joint" type="fixed">
    <origin xyz="7.12804651260376 -6.536248683929443 0.08969467133283615" rpy="0.0 0.0 1.5707966089248657"/>
    <parent link="Root"/>
    <child link="SM_Dishwasher_Base"/>
  </joint>
  <link name="SM_Dishwasher_Base">
    <inertial>
      <origin xyz="7.12804651260376 -6.536248683929443 0.08969467133283615" rpy="0.0 0.0 1.5707966089248657"/>
      <mass value="0.0"/>
      <inertia ixx="0.0" ixy="0.0" ixz="0.0" iyy="0.0" iyz="0.0" izz="0.0"/>
    </inertial>
  </link>
  <joint name="SM_Dishwasher_Tray_02_joint" type="prismatic">
    <origin xyz="-0.0073559097945690155 0.17741943895816803 0.40232786536216736" rpy="0.0 0.0 0.0"/>
    <axis xyz="0.0 -1.0 0.0"/>
    <parent link="SM_Dishwasher_Base"/>
    <child link="SM_Dishwasher_Tray_02"/>
    <limit effort="1000.0" lower="0.0" upper="0.5" velocity="1000.0"/>
  </joint>
  <link name="SM_Dishwasher_Tray_02">
    <inertial>
      <origin xyz="0.00029900201479904354 -0.002606750465929508 -0.02788277342915535" rpy="1.564607858657837 -1.5503606796264648 1.577056884765625"/>
      <mass value="8.174871444702148"/>
      <inertia ixx="0.4202146828174591" ixy="0.0" ixz="0.0" iyy="0.3023766279220581" iyz="0.0" izz="0.15317308902740479"/>
    </inertial>
  </link>
  <joint name="SM_Dishwasher_Front_joint" type="revolute">
    <origin xyz="0.0003137004387099296 -0.07611816376447678 0.0072865295223891735" rpy="1.4137167454464361e-06 7.152567036428081e-07 -1.3315807336766738e-06"/>
    <axis xyz="1.0 0.0 0.0"/>
    <parent link="SM_Dishwasher_Base"/>
    <child link="SM_Dishwasher_Front"/>
    <limit effort="1000.0" lower="0.0" upper="1.5700000524520874" velocity="1000.0"/>
  </joint>
  <link name="SM_Dishwasher_Front">
    <inertial>
      <origin xyz="-0.011108430102467537 -0.020309865474700928 0.3723928928375244" rpy="-0.012322759255766869 0.02539001777768135 1.5671337842941284"/>
      <mass value="21.572959899902344"/>
      <inertia ixx="1.60625422000885" ixy="0.0" ixz="0.0" iyy="1.008309006690979" iyz="0.0" izz="0.6173259615898132"/>
    </inertial>
  </link>
  <joint name="SM_Kitchen_Handle14_joint" type="fixed">
    <origin xyz="-0.016945090144872665 -0.05493741109967232 0.6788480281829834" rpy="-8.37747904824937e-07 1.4137226571619976e-06 1.5708035230636597"/>
    <parent link="SM_Dishwasher_Front"/>
    <child link="SM_Kitchen_Handle14"/>
  </joint>
  <link name="SM_Kitchen_Handle14">
    <inertial>
      <origin xyz="-0.01734265126287937 -4.472618456929922e-06 0.0004545578849501908" rpy="1.5707920789718628 -1.5707963705062866 0.0"/>
      <mass value="0.033401232212781906"/>
      <inertia ixx="0.00010963201930280775" ixy="0.0" ixz="0.0" iyy="0.00010809655941557139" iyz="0.0" izz="2.349011538171908e-06"/>
    </inertial>
  </link>
  <joint name="SM_Dishwasher_Tray_03_joint" type="prismatic">
    <origin xyz="-0.013126167468726635 0.1978784203529358 0.6113136410713196" rpy="0.0 0.0 0.0"/>
    <axis xyz="0.0 -1.0 0.0"/>
    <parent link="SM_Dishwasher_Base"/>
    <child link="SM_Dishwasher_Tray_03"/>
    <limit effort="1000.0" lower="0.0" upper="0.5" velocity="1000.0"/>
  </joint>
  <link name="SM_Dishwasher_Tray_03">
    <inertial>
      <origin xyz="-3.2812522143821354e-10 -0.00988641194999218 -0.01157711073756218" rpy="1.5707963705062866 -1.5707865953445435 1.5707963705062866"/>
      <mass value="5.155755043029785"/>
      <inertia ixx="0.21530850231647491" ixy="0.0" ixz="0.0" iyy="0.11622354388237" iyz="0.0" izz="0.10068675875663757"/>
    </inertial>
  </link>
  <joint name="SM_Dishwasher_Tray_01_joint" type="prismatic">
    <origin xyz="-0.007362008560448885 0.19401611387729645 0.22713592648506165" rpy="0.0 0.0 0.0"/>
    <axis xyz="0.0 -1.0 0.0"/>
    <parent link="SM_Dishwasher_Base"/>
    <child link="SM_Dishwasher_Tray_01"/>
    <limit effort="1000.0" lower="0.0" upper="0.5" velocity="1000.0"/>
  </joint>
  <link name="SM_Dishwasher_Tray_01">
    <inertial>
      <origin xyz="-0.0001159916355391033 -0.037206199020147324 -0.04113486409187317" rpy="1.5709137916564941 -1.4421941041946411 1.5726244449615479"/>
      <mass value="1.8562225103378296"/>
      <inertia ixx="0.12194844335317612" ixy="0.0" ixz="0.0" iyy="0.09177710860967636" iyz="0.0" izz="0.05106359347701073"/>
    </inertial>
  </link>
  <joint name="SM_Stove_joint" type="fixed">
    <origin xyz="6.956042289733887 -4.200277328491211 0.864665687084198" rpy="0.0 0.0 1.570798397064209"/>
    <parent link="Root"/>
    <child link="SM_Stove"/>
  </joint>
  <link name="SM_Stove">
    <inertial>
      <origin xyz="-1.4901161193847656e-08 0.0001013725996017456 -7.683411240577698e-09" rpy="3.1415927410125732 -1.570796251296997 0.0"/>
      <mass value="1.9706807136535645"/>
      <inertia ixx="0.147692009806633" ixy="0.0" ixz="0.0" iyy="0.10400468856096268" iyz="0.0" izz="0.04369489476084709"/>
    </inertial>
  </link>
  <joint name="SM_Kitchen_Island_Cover_01_joint" type="fixed">
    <origin xyz="6.583981990814209 -5.29229736328125 0.3777478039264679" rpy="0.0 0.0 1.570798397064209"/>
    <parent link="Root"/>
    <child link="SM_Kitchen_Island_Cover_01"/>
  </joint>
  <link name="SM_Kitchen_Island_Cover_01">
    <inertial>
      <origin xyz="-5.960464477539063e-08 1.2665987014770508e-07 8.940696716308594e-07" rpy="1.5707963705062866 0.0 1.5707963705062866"/>
      <mass value="56.7938232421875"/>
      <inertia ixx="50.47276306152344" ixy="0.0" ixz="0.0" iyy="46.59838104248047" iyz="0.0" izz="3.8781683444976807"/>
    </inertial>
  </link>
  <joint name="SM_Kitchen_08_Sink_Drawer_01_joint" type="prismatic">
    <origin xyz="7.010422229766846 -5.945148944854736 0.42511168122291565" rpy="0.0 0.0 1.5707964897155762"/>
    <axis xyz="0.0 -1.0 0.0"/>
    <parent link="Root"/>
    <child link="SM_Kitchen_08_Sink_Drawer_01"/>
    <limit effort="1000.0" lower="0.0" upper="0.4000000059604645" velocity="1000.0"/>
  </joint>
  <link name="SM_Kitchen_08_Sink_Drawer_01">
    <inertial>
      <origin xyz="-0.0021852985955774784 0.02051258645951748 -0.19181449711322784" rpy="-0.053303204476833344 -1.0282679796218872 1.5951522588729858"/>
      <mass value="62.20246505737305"/>
      <inertia ixx="4.275650501251221" ixy="0.0" ixz="0.0" iyy="3.480215311050415" iyz="0.0" izz="3.2226903438568115"/>
    </inertial>
  </link>
  <joint name="SM_Kitchen_Handle13_joint" type="fixed">
    <origin xyz="0.0033080391585826874 -0.24900329113006592 0.3507174551486969" rpy="0.0 0.0 1.5708022117614746"/>
    <parent link="SM_Kitchen_08_Sink_Drawer_01"/>
    <child link="SM_Kitchen_Handle13"/>
  </joint>
  <link name="SM_Kitchen_Handle13">
    <inertial>
      <origin xyz="-0.01734265126287937 -4.472618456929922e-06 0.0004545578849501908" rpy="1.5707920789718628 -1.5707963705062866 0.0"/>
      <mass value="0.033401232212781906"/>
      <inertia ixx="0.00010963201930280775" ixy="0.0" ixz="0.0" iyy="0.00010809655941557139" iyz="0.0" izz="2.349011538171908e-06"/>
    </inertial>
  </link>
  <joint name="SM_Kitchen_04_Base_joint" type="fixed">
    <origin xyz="9.269991874694824 -5.866569519042969 1.7545452117919922" rpy="0.0 0.0 -1.5707920789718628"/>
    <parent link="Root"/>
    <child link="SM_Kitchen_04_Base"/>
  </joint>
  <link name="SM_Kitchen_04_Base">
    <inertial>
      <origin xyz="0.06871644407510757 0.03571668639779091 -4.157181319897063e-05" rpy="1.5708061456680298 1.2934538972331211e-05 1.5465885400772095"/>
      <mass value="29.41886329650879"/>
      <inertia ixx="6.926770210266113" ixy="0.0" ixz="0.0" iyy="4.70819616317749" iyz="0.0" izz="2.9361281394958496"/>
    </inertial>
  </link>
  <joint name="SM_Kitchen_04_Door_02_joint" type="fixed">
    <origin xyz="-0.009312164038419724 -0.15043452382087708 -0.19994902610778809" rpy="0.0 0.0 -8.470329472543003e-22"/>
    <parent link="SM_Kitchen_04_Base"/>
    <child link="SM_Kitchen_04_Door_02"/>
  </joint>
  <link name="SM_Kitchen_04_Door_02">
    <inertial>
      <origin xyz="1.4901161193847656e-08 -0.025358743965625763 -2.2351741790771484e-08" rpy="1.5707963705062866 0.0 1.5707963705062866"/>
      <mass value="7.499030590057373"/>
      <inertia ixx="0.7190176844596863" ixy="0.0" ixz="0.0" iyy="0.6212669014930725" iyz="0.0" izz="0.09820189327001572"/>
    </inertial>
  </link>
  <joint name="SM_Kitchen_Handle6_joint" type="fixed">
    <origin xyz="0.014146553352475166 -0.04103521630167961 -0.13357147574424744" rpy="0.0 0.0 1.5707995891571045"/>
    <parent link="SM_Kitchen_04_Door_02"/>
    <child link="SM_Kitchen_Handle6"/>
  </joint>
  <link name="SM_Kitchen_Handle6">
    <inertial>
      <origin xyz="-0.01734265126287937 -4.472618456929922e-06 0.0004545578849501908" rpy="1.5707920789718628 -1.5707963705062866 0.0"/>
      <mass value="0.033401232212781906"/>
      <inertia ixx="0.00010963201930280775" ixy="0.0" ixz="0.0" iyy="0.00010809655941557139" iyz="0.0" izz="2.349011538171908e-06"/>
    </inertial>
  </link>
  <joint name="SM_Kitchen_04_Door_01_joint" type="fixed">
    <origin xyz="-0.008373536169528961 -0.17226558923721313 0.19916778802871704" rpy="0.0 0.0 -8.470329472543003e-22"/>
    <parent link="SM_Kitchen_04_Base"/>
    <child link="SM_Kitchen_04_Door_01"/>
  </joint>
  <link name="SM_Kitchen_04_Door_01">
    <inertial>
      <origin xyz="2.9802322387695312e-08 -0.0028922446072101593 -2.2351741790771484e-08" rpy="1.5707963705062866 0.0 1.5707963705062866"/>
      <mass value="7.4976396560668945"/>
      <inertia ixx="0.718884289264679" ixy="0.0" ixz="0.0" iyy="0.6211515665054321" iyz="0.0" izz="0.09818359464406967"/>
    </inertial>
  </link>
  <joint name="SM_Kitchen_09_Drawer_01_joint" type="prismatic">
    <origin xyz="7.010149002075195 -5.343630313873291 0.7535824179649353" rpy="0.0 0.0 1.570798397064209"/>
    <axis xyz="0.0 -1.0 0.0"/>
    <parent link="Root"/>
    <child link="SM_Kitchen_09_Drawer_01"/>
    <limit effort="1000.0" lower="0.0" upper="0.4000000059604645" velocity="1000.0"/>
  </joint>
  <link name="SM_Kitchen_09_Drawer_01">
    <inertial>
      <origin xyz="1.8191029238501244e-10 -0.014876341447234154 -0.01742670312523842" rpy="1.5707963705062866 -1.5428932905197144 1.5707963705062866"/>
      <mass value="5.801854133605957"/>
      <inertia ixx="0.4293452203273773" ixy="0.0" ixz="0.0" iyy="0.23229867219924927" iyz="0.0" izz="0.20578959584236145"/>
    </inertial>
  </link>
  <joint name="SM_Kitchen_Handle15_joint" type="fixed">
    <origin xyz="0.0034528339747339487 -0.25118592381477356 0.022246703505516052" rpy="0.0 0.0 1.5708003044128418"/>
    <parent link="SM_Kitchen_09_Drawer_01"/>
    <child link="SM_Kitchen_Handle15"/>
  </joint>
  <link name="SM_Kitchen_Handle15">
    <inertial>
      <origin xyz="-0.01734265126287937 -4.472618456929922e-06 0.0004545578849501908" rpy="1.5707920789718628 -1.5707963705062866 0.0"/>
      <mass value="0.033401232212781906"/>
      <inertia ixx="0.00010963201930280775" ixy="0.0" ixz="0.0" iyy="0.00010809655941557139" iyz="0.0" izz="2.349011538171908e-06"/>
    </inertial>
  </link>
  <joint name="SM_Milchbehaelter_joint" type="fixed">
    <origin xyz="9.085514068603516 -5.423364639282227 0.9194504618644714" rpy="0.0 0.0 -1.7453218698501587"/>
    <parent link="Root"/>
    <child link="SM_Milchbehaelter"/>
  </joint>
  <link name="SM_Milchbehaelter">
    <inertial>
      <origin xyz="4.011805032872929e-19 2.138363342321585e-19 -0.00034025683999061584" rpy="0.0 0.0 0.7259573936462402"/>
      <mass value="1.0175386667251587"/>
      <inertia ixx="0.0020740500185638666" ixy="0.0" ixz="0.0" iyy="0.0020740500185638666" iyz="0.0" izz="0.0012642124202102423"/>
    </inertial>
  </link>
  <joint name="SM_Kitchen_06_Base_Drawer_03_joint" type="prismatic">
    <origin xyz="9.12474536895752 -6.157220363616943 0.22507452964782715" rpy="0.0 0.0 -1.5707920789718628"/>
    <axis xyz="0.0 -1.0 0.0"/>
    <parent link="Root"/>
    <child link="SM_Kitchen_06_Base_Drawer_03"/>
    <limit effort="1000.0" lower="0.0" upper="0.4000000059604645" velocity="1000.0"/>
  </joint>
  <link name="SM_Kitchen_06_Base_Drawer_03">
    <inertial>
      <origin xyz="3.941088788650404e-09 -0.053097523748874664 -0.06891762465238571" rpy="0.0 -1.3160065412521362 1.5707963705062866"/>
      <mass value="7.23633337020874"/>
      <inertia ixx="0.40906497836112976" ixy="0.0" ixz="0.0" iyy="0.34911292791366577" iyz="0.0" izz="0.17803430557250977"/>
    </inertial>
  </link>
  <joint name="SM_Kitchen_Handle10_joint" type="fixed">
    <origin xyz="0.004023605026304722 -0.24711915850639343 0.15116584300994873" rpy="0.0 0.0 1.5707995891571045"/>
    <parent link="SM_Kitchen_06_Base_Drawer_03"/>
    <child link="SM_Kitchen_Handle10"/>
  </joint>
  <link name="SM_Kitchen_Handle10">
    <inertial>
      <origin xyz="-0.01734265126287937 -4.472618456929922e-06 0.0004545578849501908" rpy="1.5707920789718628 -1.5707963705062866 0.0"/>
      <mass value="0.033401232212781906"/>
      <inertia ixx="0.00010963201930280775" ixy="0.0" ixz="0.0" iyy="0.00010809655941557139" iyz="0.0" izz="2.349011538171908e-06"/>
    </inertial>
  </link>
  <joint name="SM_Kitchen_10_Drawer_03_joint" type="prismatic">
    <origin xyz="7.00963830947876 -4.844245910644531 0.2245825082063675" rpy="0.0 0.0 1.570798397064209"/>
    <axis xyz="0.0 -1.0 0.0"/>
    <parent link="Root"/>
    <child link="SM_Kitchen_10_Drawer_03"/>
    <limit effort="1000.0" lower="0.0" upper="0.4000000059604645" velocity="1000.0"/>
  </joint>
  <link name="SM_Kitchen_10_Drawer_03">
    <inertial>
      <origin xyz="3.941088788650404e-09 -0.053097523748874664 -0.06891762465238571" rpy="0.0 -1.3160065412521362 1.5707963705062866"/>
      <mass value="7.23633337020874"/>
      <inertia ixx="0.40906497836112976" ixy="0.0" ixz="0.0" iyy="0.34911292791366577" iyz="0.0" izz="0.17803430557250977"/>
    </inertial>
  </link>
  <joint name="SM_Kitchen_Handle20_joint" type="fixed">
    <origin xyz="0.0026740296743810177 -0.24916930496692657 0.16028167307376862" rpy="0.0 0.0 1.5708003044128418"/>
    <parent link="SM_Kitchen_10_Drawer_03"/>
    <child link="SM_Kitchen_Handle20"/>
  </joint>
  <link name="SM_Kitchen_Handle20">
    <inertial>
      <origin xyz="-0.01734265126287937 -4.472618456929922e-06 0.0004545578849501908" rpy="1.5707920789718628 -1.5707963705062866 0.0"/>
      <mass value="0.033401232212781906"/>
      <inertia ixx="0.00010963201930280775" ixy="0.0" ixz="0.0" iyy="0.00010809655941557139" iyz="0.0" izz="2.349011538171908e-06"/>
    </inertial>
  </link>
  <joint name="SM_Kaffeemaschine_joint" type="fixed">
    <origin xyz="9.108317375183105 -5.781892776489258 1.054582118988037" rpy="0.0 0.0 -1.7453218698501587"/>
    <parent link="Root"/>
    <child link="SM_Kaffeemaschine"/>
  </joint>
  <link name="SM_Kaffeemaschine">
    <inertial>
      <origin xyz="0.011644275858998299 0.02544061467051506 0.0024499050341546535" rpy="0.7526939511299133 0.09484107047319412 -0.06819579005241394"/>
      <mass value="41.93296432495117"/>
      <inertia ixx="1.2354234457015991" ixy="0.0" ixz="0.0" iyy="1.00127375125885" iyz="0.0" izz="0.8506510853767395"/>
    </inertial>
  </link>
  <joint name="SM_Kaffeemaschine_BohnenDeckel_joint" type="fixed">
    <origin xyz="0.04730023071169853 0.07816902548074722 0.1899539977312088" rpy="0.0 0.0 0.0"/>
    <parent link="SM_Kaffeemaschine"/>
    <child link="SM_Kaffeemaschine_BohnenDeckel"/>
  </joint>
  <link name="SM_Kaffeemaschine_BohnenDeckel">
    <inertial>
      <origin xyz="0.04730023071169853 0.07816902548074722 0.1899539977312088" rpy="0.0 0.0 0.0"/>
      <mass value="0.0"/>
      <inertia ixx="0.0" ixy="0.0" ixz="0.0" iyy="0.0" iyz="0.0" izz="0.0"/>
    </inertial>
  </link>
  <joint name="SM_Kaffeemaschine_Metallteil_joint" type="fixed">
    <origin xyz="-0.0002547749027144164 -0.1459856480360031 0.0403040312230587" rpy="0.0 0.0 0.0"/>
    <parent link="SM_Kaffeemaschine"/>
    <child link="SM_Kaffeemaschine_Metallteil"/>
  </joint>
  <link name="SM_Kaffeemaschine_Metallteil">
    <inertial>
      <origin xyz="-0.0002547749027144164 -0.1459856480360031 0.0403040312230587" rpy="0.0 0.0 0.0"/>
      <mass value="0.0"/>
      <inertia ixx="0.0" ixy="0.0" ixz="0.0" iyy="0.0" iyz="0.0" izz="0.0"/>
    </inertial>
  </link>
  <joint name="SM_Kaffeemaschine_Gitter_joint" type="fixed">
    <origin xyz="1.034321030601859e-06 -0.16572162508964539 -0.15607032179832458" rpy="0.0 0.0 0.0"/>
    <parent link="SM_Kaffeemaschine"/>
    <child link="SM_Kaffeemaschine_Gitter"/>
  </joint>
  <link name="SM_Kaffeemaschine_Gitter">
    <inertial>
      <origin xyz="1.034321030601859e-06 -0.16572162508964539 -0.15607032179832458" rpy="0.0 0.0 0.0"/>
      <mass value="0.0"/>
      <inertia ixx="0.0" ixy="0.0" ixz="0.0" iyy="0.0" iyz="0.0" izz="0.0"/>
    </inertial>
  </link>
  <joint name="SM_Kaffeemaschine_WasserbehaelterDeckel_joint" type="fixed">
    <origin xyz="-0.11118394881486893 0.052899494767189026 0.18963004648685455" rpy="0.0 0.0 0.0"/>
    <parent link="SM_Kaffeemaschine"/>
    <child link="SM_Kaffeemaschine_WasserbehaelterDeckel"/>
  </joint>
  <link name="SM_Kaffeemaschine_WasserbehaelterDeckel">
    <inertial>
      <origin xyz="-0.11118394881486893 0.052899494767189026 0.18963004648685455" rpy="0.0 0.0 0.0"/>
      <mass value="0.0"/>
      <inertia ixx="0.0" ixy="0.0" ixz="0.0" iyy="0.0" iyz="0.0" izz="0.0"/>
    </inertial>
  </link>
  <joint name="SM_Kaffeemaschine_Wasserbehaelter_joint" type="fixed">
    <origin xyz="-0.11810481548309326 0.05265658721327782 0.061977993696928024" rpy="0.0 0.0 0.0"/>
    <parent link="SM_Kaffeemaschine"/>
    <child link="SM_Kaffeemaschine_Wasserbehaelter"/>
  </joint>
  <link name="SM_Kaffeemaschine_Wasserbehaelter">
    <inertial>
      <origin xyz="-0.11810481548309326 0.05265658721327782 0.061977993696928024" rpy="0.0 0.0 0.0"/>
      <mass value="0.0"/>
      <inertia ixx="0.0" ixy="0.0" ixz="0.0" iyy="0.0" iyz="0.0" izz="0.0"/>
    </inertial>
  </link>
  <joint name="SM_Kitchen_06_Base_Drawer_02_joint" type="prismatic">
    <origin xyz="9.124488830566406 -6.157266616821289 0.554952085018158" rpy="0.0 0.0 -1.5707920789718628"/>
    <axis xyz="0.0 -1.0 0.0"/>
    <parent link="Root"/>
    <child link="SM_Kitchen_06_Base_Drawer_02"/>
    <limit effort="1000.0" lower="0.0" upper="0.4000000059604645" velocity="1000.0"/>
  </joint>
  <link name="SM_Kitchen_06_Base_Drawer_02">
    <inertial>
      <origin xyz="-7.82054476733407e-10 -0.023389536887407303 -0.04450542479753494" rpy="0.0 -1.4745656251907349 1.5707963705062866"/>
      <mass value="6.215494155883789"/>
      <inertia ixx="0.34396618604660034" ixy="0.0" ixz="0.0" iyy="0.2639531195163727" iyz="0.0" izz="0.13102813065052032"/>
    </inertial>
  </link>
  <joint name="SM_Kitchen_Handle8_joint" type="fixed">
    <origin xyz="0.003977219574153423 -0.24686279892921448 0.08541778475046158" rpy="0.0 0.0 1.5707995891571045"/>
    <parent link="SM_Kitchen_06_Base_Drawer_02"/>
    <child link="SM_Kitchen_Handle8"/>
  </joint>
  <link name="SM_Kitchen_Handle8">
    <inertial>
      <origin xyz="-0.01734265126287937 -4.472618456929922e-06 0.0004545578849501908" rpy="1.5707920789718628 -1.5707963705062866 0.0"/>
      <mass value="0.033401232212781906"/>
      <inertia ixx="0.00010963201930280775" ixy="0.0" ixz="0.0" iyy="0.00010809655941557139" iyz="0.0" izz="2.349011538171908e-06"/>
    </inertial>
  </link>
  <joint name="SM_Kitchen_10_Drawer_01_joint" type="prismatic">
    <origin xyz="7.010195255279541 -4.845238208770752 0.7542022466659546" rpy="0.0 0.0 1.570798397064209"/>
    <axis xyz="0.0 -1.0 0.0"/>
    <parent link="Root"/>
    <child link="SM_Kitchen_10_Drawer_01"/>
    <limit effort="1000.0" lower="0.0" upper="0.4000000059604645" velocity="1000.0"/>
  </joint>
  <link name="SM_Kitchen_10_Drawer_01">
    <inertial>
      <origin xyz="1.0153192731010563e-09 -0.01303133275359869 -0.01641898788511753" rpy="0.0 -1.545478105545044 1.5707963705062866"/>
      <mass value="4.332450866699219"/>
      <inertia ixx="0.21865983307361603" ixy="0.0" ixz="0.0" iyy="0.1454179883003235" iyz="0.0" izz="0.07959701120853424"/>
    </inertial>
  </link>
  <joint name="SM_Kitchen_Handle18_joint" type="fixed">
    <origin xyz="0.0036664623767137527 -0.2486126720905304 0.021626891568303108" rpy="0.0 0.0 1.5708003044128418"/>
    <parent link="SM_Kitchen_10_Drawer_01"/>
    <child link="SM_Kitchen_Handle18"/>
  </joint>
  <link name="SM_Kitchen_Handle18">
    <inertial>
      <origin xyz="-0.01734265126287937 -4.472618456929922e-06 0.0004545578849501908" rpy="1.5707920789718628 -1.5707963705062866 0.0"/>
      <mass value="0.033401232212781906"/>
      <inertia ixx="0.00010963201930280775" ixy="0.0" ixz="0.0" iyy="0.00010809655941557139" iyz="0.0" izz="2.349011538171908e-06"/>
    </inertial>
  </link>
  <joint name="SM_Kitchen_05_Base_Drawer_01_joint" type="prismatic">
    <origin xyz="9.124837875366211 -5.657802581787109 0.7534152269363403" rpy="0.0 0.0 -1.5707920789718628"/>
    <axis xyz="0.0 -1.0 0.0"/>
    <parent link="Root"/>
    <child link="SM_Kitchen_05_Base_Drawer_01"/>
    <limit effort="1000.0" lower="0.0" upper="0.4000000059604645" velocity="1000.0"/>
  </joint>
  <link name="SM_Kitchen_05_Base_Drawer_01">
    <inertial>
      <origin xyz="1.8191029238501244e-10 -0.014876341447234154 -0.01742670312523842" rpy="1.5707963705062866 -1.5428932905197144 1.5707963705062866"/>
      <mass value="5.801854133605957"/>
      <inertia ixx="0.4293452203273773" ixy="0.0" ixz="0.0" iyy="0.23229867219924927" iyz="0.0" izz="0.20578959584236145"/>
    </inertial>
  </link>
  <joint name="SM_Kitchen_Handle12_joint" type="fixed">
    <origin xyz="-0.0014231835957616568 -0.24980711936950684 0.016769561916589737" rpy="0.0 0.0 1.5707995891571045"/>
    <parent link="SM_Kitchen_05_Base_Drawer_01"/>
    <child link="SM_Kitchen_Handle12"/>
  </joint>
  <link name="SM_Kitchen_Handle12">
    <inertial>
      <origin xyz="-0.01734265126287937 -4.472618456929922e-06 0.0004545578849501908" rpy="1.5707920789718628 -1.5707963705062866 0.0"/>
      <mass value="0.033401232212781906"/>
      <inertia ixx="0.00010963201930280775" ixy="0.0" ixz="0.0" iyy="0.00010809655941557139" iyz="0.0" izz="2.349011538171908e-06"/>
    </inertial>
  </link>
  <joint name="SM_Kitchen_05_Base_Drawer_02_joint" type="prismatic">
    <origin xyz="9.124430656433105 -5.657596111297607 0.5553614497184753" rpy="0.0 0.0 -1.5707920789718628"/>
    <axis xyz="0.0 -1.0 0.0"/>
    <parent link="Root"/>
    <child link="SM_Kitchen_05_Base_Drawer_02"/>
    <limit effort="1000.0" lower="0.0" upper="0.4000000059604645" velocity="1000.0"/>
  </joint>
  <link name="SM_Kitchen_05_Base_Drawer_02">
    <inertial>
      <origin xyz="-1.3268040000014025e-09 -0.025337589904665947 -0.0437018945813179" rpy="0.0 -1.4715920686721802 1.5707963705062866"/>
      <mass value="8.477095603942871"/>
      <inertia ixx="0.6637729406356812" ixy="0.0" ixz="0.0" iyy="0.38019412755966187" iyz="0.0" izz="0.355472594499588"/>
    </inertial>
  </link>
  <joint name="SM_Kitchen_Handle7_joint" type="fixed">
    <origin xyz="-0.0010679628467187285 -0.2507079839706421 0.08500839024782181" rpy="0.0 0.0 1.5707995891571045"/>
    <parent link="SM_Kitchen_05_Base_Drawer_02"/>
    <child link="SM_Kitchen_Handle7"/>
  </joint>
  <link name="SM_Kitchen_Handle7">
    <inertial>
      <origin xyz="-0.01734265126287937 -4.472618456929922e-06 0.0004545578849501908" rpy="1.5707920789718628 -1.5707963705062866 0.0"/>
      <mass value="0.033401232212781906"/>
      <inertia ixx="0.00010963201930280775" ixy="0.0" ixz="0.0" iyy="0.00010809655941557139" iyz="0.0" izz="2.349011538171908e-06"/>
    </inertial>
  </link>
  <joint name="SM_Kitchen_Island_Cover_4_joint" type="fixed">
    <origin xyz="9.17965030670166 -6.367841720581055 0.3734469413757324" rpy="0.0 0.0 -1.5707899332046509"/>
    <parent link="Root"/>
    <child link="SM_Kitchen_Island_Cover_4"/>
  </joint>
  <link name="SM_Kitchen_Island_Cover_4">
    <inertial>
      <origin xyz="5.513429641723633e-07 5.960464477539063e-08 1.4156103134155273e-07" rpy="0.0 0.0 0.0"/>
      <mass value="12.20611572265625"/>
      <inertia ixx="1.2901133298873901" ixy="0.0" ixz="0.0" iyy="0.820485532283783" iyz="0.0" izz="0.47044143080711365"/>
    </inertial>
  </link>
  <joint name="SM_Kitchen_01_Shelf2_joint" type="fixed">
    <origin xyz="9.168460845947266 -4.048857688903809 1.5859078168869019" rpy="0.0 0.0 -1.5707899332046509"/>
    <parent link="Root"/>
    <child link="SM_Kitchen_01_Shelf2"/>
  </joint>
  <link name="SM_Kitchen_01_Shelf2">
    <inertial>
      <origin xyz="7.599592208862305e-07 1.043081283569336e-07 0.004950471222400665" rpy="3.1415927410125732 -1.570796251296997 0.0"/>
      <mass value="4.49151611328125"/>
      <inertia ixx="0.22450226545333862" ixy="0.0" ixz="0.0" iyy="0.11827681213617325" iyz="0.0" izz="0.10639383643865585"/>
    </inertial>
  </link>
  <joint name="SM_Kitchen_11_Base_Drawer_03_joint" type="prismatic">
    <origin xyz="7.01006555557251 -4.195715427398682 0.22396689653396606" rpy="0.0 0.0 1.570798397064209"/>
    <axis xyz="0.0 -1.0 0.0"/>
    <parent link="Root"/>
    <child link="SM_Kitchen_11_Base_Drawer_03"/>
    <limit effort="1000.0" lower="0.0" upper="0.4000000059604645" velocity="1000.0"/>
  </joint>
  <link name="SM_Kitchen_11_Base_Drawer_03">
    <inertial>
      <origin xyz="2.4347481808462135e-09 -0.06014884263277054 -0.06300604343414307" rpy="1.5707963705062866 -1.3135372400283813 1.5707963705062866"/>
      <mass value="14.181320190429688"/>
      <inertia ixx="1.7410063743591309" ixy="0.0" ixz="0.0" iyy="1.2510854005813599" iyz="0.0" izz="0.7377597689628601"/>
    </inertial>
  </link>
  <joint name="SM_Kitchen_Handle23_joint" type="fixed">
    <origin xyz="0.011655965819954872 -0.24802431464195251 0.16089728474617004" rpy="0.0 0.0 1.5708003044128418"/>
    <parent link="SM_Kitchen_11_Base_Drawer_03"/>
    <child link="SM_Kitchen_Handle23"/>
  </joint>
  <link name="SM_Kitchen_Handle23">
    <inertial>
      <origin xyz="-0.01734265126287937 -4.472618456929922e-06 0.0004545578849501908" rpy="1.5707920789718628 -1.5707963705062866 0.0"/>
      <mass value="0.033401232212781906"/>
      <inertia ixx="0.00010963201930280775" ixy="0.0" ixz="0.0" iyy="0.00010809655941557139" iyz="0.0" izz="2.349011538171908e-06"/>
    </inertial>
  </link>
  <joint name="SM_Kitchen_02_Base_joint" type="fixed">
    <origin xyz="9.17232608795166 -4.549736499786377 1.0898194313049316" rpy="0.0 0.0 -1.5707899332046509"/>
    <parent link="Root"/>
    <child link="SM_Kitchen_02_Base"/>
  </joint>
  <link name="SM_Kitchen_02_Base">
    <inertial>
      <origin xyz="9.17232608795166 -4.549736499786377 1.0898194313049316" rpy="0.0 0.0 -1.5707899332046509"/>
      <mass value="0.0"/>
      <inertia ixx="0.0" ixy="0.0" ixz="0.0" iyy="0.0" iyz="0.0" izz="0.0"/>
    </inertial>
  </link>
  <joint name="SM_Kitchen_02_Shelf_joint" type="fixed">
    <origin xyz="-0.00043337122770026326 -0.0033837861847132444 0.790361762046814" rpy="0.0 0.0 0.0"/>
    <parent link="SM_Kitchen_02_Base"/>
    <child link="SM_Kitchen_02_Shelf"/>
  </joint>
  <link name="SM_Kitchen_02_Shelf">
    <inertial>
      <origin xyz="-0.00043337122770026326 -0.0033837861847132444 0.790361762046814" rpy="0.0 0.0 0.0"/>
      <mass value="0.0"/>
      <inertia ixx="0.0" ixy="0.0" ixz="0.0" iyy="0.0" iyz="0.0" izz="0.0"/>
    </inertial>
  </link>
  <joint name="SM_Kitchen_02_Drawer_3_joint" type="fixed">
    <origin xyz="-0.0009620015043765306 -0.013681634329259396 0.4227500855922699" rpy="0.0 0.0 0.0"/>
    <parent link="SM_Kitchen_02_Base"/>
    <child link="SM_Kitchen_02_Drawer_3"/>
  </joint>
  <link name="SM_Kitchen_02_Drawer_3">
    <inertial>
      <origin xyz="-0.0009620015043765306 -0.013681634329259396 0.4227500855922699" rpy="0.0 0.0 0.0"/>
      <mass value="0.0"/>
      <inertia ixx="0.0" ixy="0.0" ixz="0.0" iyy="0.0" iyz="0.0" izz="0.0"/>
    </inertial>
  </link>
  <joint name="SM_Kitchen_02_Drawer_4_joint" type="fixed">
    <origin xyz="-0.0009644429665058851 -0.01369384117424488 -0.24243728816509247" rpy="0.0 0.0 0.0"/>
    <parent link="SM_Kitchen_02_Base"/>
    <child link="SM_Kitchen_02_Drawer_4"/>
  </joint>
  <link name="SM_Kitchen_02_Drawer_4">
    <inertial>
      <origin xyz="-0.0009644429665058851 -0.01369384117424488 -0.24243728816509247" rpy="0.0 0.0 0.0"/>
      <mass value="0.0"/>
      <inertia ixx="0.0" ixy="0.0" ixz="0.0" iyy="0.0" iyz="0.0" izz="0.0"/>
    </inertial>
  </link>
  <joint name="SM_Kitchen_02_Drawer_6_joint" type="fixed">
    <origin xyz="-0.0009644429665058851 -0.01369384117424488 -0.9551920890808105" rpy="0.0 0.0 0.0"/>
    <parent link="SM_Kitchen_02_Base"/>
    <child link="SM_Kitchen_02_Drawer_6"/>
  </joint>
  <link name="SM_Kitchen_02_Drawer_6">
    <inertial>
      <origin xyz="-0.0009644429665058851 -0.01369384117424488 -0.9551920890808105" rpy="0.0 0.0 0.0"/>
      <mass value="0.0"/>
      <inertia ixx="0.0" ixy="0.0" ixz="0.0" iyy="0.0" iyz="0.0" izz="0.0"/>
    </inertial>
  </link>
  <joint name="SM_Kitchen_02_Drawer_01_joint" type="fixed">
    <origin xyz="-0.001344023854471743 -0.004648428875952959 0.5804628133773804" rpy="0.0 0.0 0.0"/>
    <parent link="SM_Kitchen_02_Base"/>
    <child link="SM_Kitchen_02_Drawer_01"/>
  </joint>
  <link name="SM_Kitchen_02_Drawer_01">
    <inertial>
      <origin xyz="-0.001344023854471743 -0.004648428875952959 0.5804628133773804" rpy="0.0 0.0 0.0"/>
      <mass value="0.0"/>
      <inertia ixx="0.0" ixy="0.0" ixz="0.0" iyy="0.0" iyz="0.0" izz="0.0"/>
    </inertial>
  </link>
  <joint name="SM_Kitchen_02_Drawer_5_joint" type="fixed">
    <origin xyz="-0.0009644429665058851 -0.01369384117424488 -0.5180959701538086" rpy="0.0 0.0 0.0"/>
    <parent link="SM_Kitchen_02_Base"/>
    <child link="SM_Kitchen_02_Drawer_5"/>
  </joint>
  <link name="SM_Kitchen_02_Drawer_5">
    <inertial>
      <origin xyz="-0.0009644429665058851 -0.01369384117424488 -0.5180959701538086" rpy="0.0 0.0 0.0"/>
      <mass value="0.0"/>
      <inertia ixx="0.0" ixy="0.0" ixz="0.0" iyy="0.0" iyz="0.0" izz="0.0"/>
    </inertial>
  </link>
  <joint name="SM_Kitchen_02_Drawer_02_joint" type="fixed">
    <origin xyz="-0.0009620015043765306 -0.013681634329259396 0.14289641380310059" rpy="0.0 0.0 0.0"/>
    <parent link="SM_Kitchen_02_Base"/>
    <child link="SM_Kitchen_02_Drawer_02"/>
  </joint>
  <link name="SM_Kitchen_02_Drawer_02">
    <inertial>
      <origin xyz="-0.0009620015043765306 -0.013681634329259396 0.14289641380310059" rpy="0.0 0.0 0.0"/>
      <mass value="0.0"/>
      <inertia ixx="0.0" ixy="0.0" ixz="0.0" iyy="0.0" iyz="0.0" izz="0.0"/>
    </inertial>
  </link>
  <joint name="SM_Kitchen_02_Door_joint" type="revolute">
    <origin xyz="-0.17997504770755768 -0.29853156208992004 0.0010586547432467341" rpy="0.0 0.0 -9.611011801951425e-16"/>
    <axis xyz="0.0 0.0 -1.0"/>
    <parent link="SM_Kitchen_02_Base"/>
    <child link="SM_Kitchen_02_Door"/>
    <limit effort="1000.0" lower="0.0" upper="1.5707000494003296" velocity="1000.0"/>
  </joint>
  <link name="SM_Kitchen_02_Door">
    <inertial>
      <origin xyz="0.1809278130531311 0.013537779450416565 0.0" rpy="0.0 0.0 1.5707963705062866"/>
      <mass value="16.002307891845703"/>
      <inertia ixx="6.23053503036499" ixy="0.0" ixz="0.0" iyy="6.020884990692139" iyz="0.0" izz="0.21061018109321594"/>
    </inertial>
  </link>
  <joint name="SM_Kitchen_Handle5_joint" type="fixed">
    <origin xyz="0.2588561773300171 -0.0018449161434546113 -0.05118865892291069" rpy="0.0 0.0 1.5707974433898926"/>
    <parent link="SM_Kitchen_02_Door"/>
    <child link="SM_Kitchen_Handle5"/>
  </joint>
  <link name="SM_Kitchen_Handle5">
    <inertial>
      <origin xyz="-0.01734265126287937 -4.472618456929922e-06 0.0004545578849501908" rpy="1.5707920789718628 -1.5707963705062866 0.0"/>
      <mass value="0.033401232212781906"/>
      <inertia ixx="0.00010963201930280775" ixy="0.0" ixz="0.0" iyy="0.00010809655941557139" iyz="0.0" izz="2.349011538171908e-06"/>
    </inertial>
  </link>
  <joint name="SM_Kitchen_01_Shelf_joint" type="fixed">
    <origin xyz="9.168460845947266 -4.048857688903809 1.7998199462890625" rpy="0.0 0.0 -1.5707899332046509"/>
    <parent link="Root"/>
    <child link="SM_Kitchen_01_Shelf"/>
  </joint>
  <link name="SM_Kitchen_01_Shelf">
    <inertial>
      <origin xyz="7.599592208862305e-07 1.043081283569336e-07 0.004950471222400665" rpy="3.1415927410125732 -1.570796251296997 0.0"/>
      <mass value="4.49151611328125"/>
      <inertia ixx="0.22450226545333862" ixy="0.0" ixz="0.0" iyy="0.11827681213617325" iyz="0.0" izz="0.10639383643865585"/>
    </inertial>
  </link>
  <joint name="SM_Counter_Watertab_joint" type="fixed">
    <origin xyz="6.911593914031982 -5.927649974822998 1.0144516229629517" rpy="0.0 0.0 1.570798397064209"/>
    <parent link="Root"/>
    <child link="SM_Counter_Watertab"/>
  </joint>
  <link name="SM_Counter_Watertab">
    <inertial>
      <origin xyz="-0.015890955924987793 0.07901770621538162 -0.01165551133453846" rpy="0.5522939562797546 -0.01961176097393036 -0.004394977353513241"/>
      <mass value="0.418657511472702"/>
      <inertia ixx="0.006341776344925165" ixy="0.0" ixz="0.0" iyy="0.005704652052372694" iyz="0.0" izz="0.0008735389565117657"/>
    </inertial>
  </link>
  <joint name="SM_Counter_Sink_Tap_On_Off_joint" type="revolute">
    <origin xyz="0.04055444151163101 0.11371085047721863 -0.07370452582836151" rpy="0.0 0.0 -3.1415884494781494"/>
    <axis xyz="0.0 -1.0 0.0"/>
    <parent link="SM_Counter_Watertab"/>
    <child link="SM_Counter_Sink_Tap"/>
    <limit effort="1000.0" lower="0.0" upper="0.5" velocity="1000.0"/>
  </joint>
  <joint name="SM_Counter_Sink_Tap_Hot_Cold_joint" type="revolute">
    <origin xyz="0.04055444151163101 0.11371085047721863 -0.07370452582836151" rpy="0.0 0.0 -3.1415884494781494"/>
    <axis xyz="1.0 0.0 0.0"/>
    <parent link="SM_Counter_Watertab"/>
    <child link="SM_Counter_Sink_Tap"/>
    <limit effort="1000.0" lower="-0.7070000171661377" upper="0.7070000171661377" velocity="1000.0"/>
  </joint>
  <link name="SM_Counter_Sink_Tap">
    <inertial>
      <origin xyz="-0.010115343146026134 -2.043005764562622e-09 0.005561438854783773" rpy="-0.00020050544117111713 0.0016149148577824235 -4.762337630381808e-05"/>
      <mass value="0.035425398498773575"/>
      <inertia ixx="1.5730618542875163e-05" ixy="0.0" ixz="0.0" iyy="1.2658968444156926e-05" iyz="0.0" izz="5.448486717796186e-06"/>
    </inertial>
  </link>
  <joint name="SM_Oven_joint" type="fixed">
    <origin xyz="8.89363956451416 -4.05180549621582 0.6991637945175171" rpy="0.0 0.0 -1.5708000659942627"/>
    <parent link="Root"/>
    <child link="SM_Oven"/>
  </joint>
  <link name="SM_Oven">
    <inertial>
      <origin xyz="-0.0021508766803890467 0.29440826177597046 0.33678150177001953" rpy="-0.001087674987502396 -0.5558122396469116 1.5660420656204224"/>
      <mass value="81.7639389038086"/>
      <inertia ixx="6.139829158782959" ixy="0.0" ixz="0.0" iyy="5.195878982543945" iyz="0.0" izz="4.567628383636475"/>
    </inertial>
  </link>
  <joint name="SM_Oven_Tray_joint" type="fixed">
    <origin xyz="0.00025909283431246877 0.24592773616313934 0.2921999990940094" rpy="0.0 0.0 0.0"/>
    <parent link="SM_Oven"/>
    <child link="SM_Oven_Tray"/>
  </joint>
  <link name="SM_Oven_Tray">
    <inertial>
      <origin xyz="0.00025909283431246877 0.24592773616313934 0.2921999990940094" rpy="0.0 0.0 0.0"/>
      <mass value="0.0"/>
      <inertia ixx="0.0" ixy="0.0" ixz="0.0" iyy="0.0" iyz="0.0" izz="0.0"/>
    </inertial>
  </link>
  <joint name="SM_Oven_Door_joint" type="fixed">
    <origin xyz="0.0 0.0 0.0" rpy="-1.5707900524139404 -3.3335788884869544e-06 1.5978966985130683e-06"/>
    <parent link="SM_Oven"/>
    <child link="SM_Oven_Door"/>
  </joint>
  <link name="SM_Oven_Door">
    <inertial>
      <origin xyz="-0.0017754633445292711 -0.22805458307266235 0.004917503800243139" rpy="0.8128138780593872 -1.5706806182861328 2.328763961791992"/>
      <mass value="9.180037498474121"/>
      <inertia ixx="0.39040935039520264" ixy="0.0" ixz="0.0" iyy="0.2274288833141327" iyz="0.0" izz="0.16504892706871033"/>
    </inertial>
  </link>
  <joint name="SM_Oven_Grid_joint" type="fixed">
    <origin xyz="-0.0007271664799191058 0.2274804562330246 0.2197953760623932" rpy="0.0 0.0 0.0"/>
    <parent link="SM_Oven"/>
    <child link="SM_Oven_Grid"/>
  </joint>
  <link name="SM_Oven_Grid">
    <inertial>
      <origin xyz="-0.0007271664799191058 0.2274804562330246 0.2197953760623932" rpy="0.0 0.0 0.0"/>
      <mass value="0.0"/>
      <inertia ixx="0.0" ixy="0.0" ixz="0.0" iyy="0.0" iyz="0.0" izz="0.0"/>
    </inertial>
  </link>
  <joint name="SM_Kitchen_09_Drawer_02_joint" type="prismatic">
    <origin xyz="7.0100998878479 -5.344728946685791 0.5564426779747009" rpy="0.0 0.0 1.570798635482788"/>
    <axis xyz="0.0 -1.0 0.0"/>
    <parent link="Root"/>
    <child link="SM_Kitchen_09_Drawer_02"/>
    <limit effort="1000.0" lower="0.0" upper="0.4000000059604645" velocity="1000.0"/>
  </joint>
  <link name="SM_Kitchen_09_Drawer_02">
    <inertial>
      <origin xyz="-1.3268040000014025e-09 -0.025337589904665947 -0.0437018945813179" rpy="0.0 -1.4715920686721802 1.5707963705062866"/>
      <mass value="8.477095603942871"/>
      <inertia ixx="0.6637729406356812" ixy="0.0" ixz="0.0" iyy="0.38019412755966187" iyz="0.0" izz="0.355472594499588"/>
    </inertial>
  </link>
  <joint name="SM_Kitchen_Handle16_joint" type="fixed">
    <origin xyz="0.004551433026790619 -0.2512347400188446 0.08721404522657394" rpy="0.0 0.0 1.5708001852035522"/>
    <parent link="SM_Kitchen_09_Drawer_02"/>
    <child link="SM_Kitchen_Handle16"/>
  </joint>
  <link name="SM_Kitchen_Handle16">
    <inertial>
      <origin xyz="-0.01734265126287937 -4.472618456929922e-06 0.0004545578849501908" rpy="1.5707920789718628 -1.5707963705062866 0.0"/>
      <mass value="0.033401232212781906"/>
      <inertia ixx="0.00010963201930280775" ixy="0.0" ixz="0.0" iyy="0.00010809655941557139" iyz="0.0" izz="2.349011538171908e-06"/>
    </inertial>
  </link>
  <joint name="SM_Kitchen_03_Fridge_joint" type="fixed">
    <origin xyz="9.177248001098633 -5.052584648132324 1.0903091430664062" rpy="0.0 0.0 -1.5707976818084717"/>
    <parent link="Root"/>
    <child link="SM_Kitchen_03_Fridge"/>
  </joint>
  <link name="SM_Kitchen_03_Fridge">
    <inertial>
      <origin xyz="-0.0014405125984922051 0.00322521454654634 0.33573201298713684" rpy="-0.00038039061473682523 0.0003713861224241555 1.5707523822784424"/>
      <mass value="148.79736328125"/>
      <inertia ixx="100.94480895996094" ixy="0.0" ixz="0.0" iyy="97.9454345703125" iyz="0.0" izz="10.4905424118042"/>
    </inertial>
  </link>
  <joint name="SM_Fridge_Base_joint" type="fixed">
    <origin xyz="0.0029211679939180613 -0.01918944902718067 -0.08169372379779816" rpy="0.0 0.0 7.723167072981596e-06"/>
    <parent link="SM_Kitchen_03_Fridge"/>
    <child link="SM_Fridge_Base"/>
  </joint>
  <link name="SM_Fridge_Base">
    <inertial>
      <origin xyz="8.616805047267917e-08 0.06489147990942001 -0.05847245082259178" rpy="0.0 -0.008151154033839703 1.5707963705062866"/>
      <mass value="183.64126586914062"/>
      <inertia ixx="60.56223678588867" ixy="0.0" ixz="0.0" iyy="57.430660247802734" iyz="0.0" izz="10.04569149017334"/>
    </inertial>
  </link>
  <joint name="SM_Fridge_Drawer_02_joint" type="prismatic">
    <origin xyz="0.0019896470475941896 -0.015473645180463791 -0.04961257800459862" rpy="0.0 0.0 -8.470329472543003e-22"/>
    <axis xyz="0.0 -1.0 0.0"/>
    <parent link="SM_Fridge_Base"/>
    <child link="SM_Fridge_Drawer_02"/>
    <limit effort="1000.0" lower="0.0" upper="0.3499999940395355" velocity="1000.0"/>
  </joint>
  <link name="SM_Fridge_Drawer_02">
    <inertial>
      <origin xyz="-5.4779142999450414e-08 -0.028102736920118332 -0.036860328167676926" rpy="1.5707963705062866 -1.5566058158874512 1.5707963705062866"/>
      <mass value="4.684443473815918"/>
      <inertia ixx="0.13950450718402863" ixy="0.0" ixz="0.0" iyy="0.09457025676965714" iyz="0.0" izz="0.05750653147697449"/>
    </inertial>
  </link>
  <joint name="SM_Fridge_Drawer_04_joint" type="prismatic">
    <origin xyz="-0.005080750677734613 -0.028845181688666344 -0.5329980254173279" rpy="0.0 0.0 -8.470329472543003e-22"/>
    <axis xyz="0.0 -1.0 0.0"/>
    <parent link="SM_Fridge_Base"/>
    <child link="SM_Fridge_Drawer_04"/>
    <limit effort="1000.0" lower="0.0" upper="0.3499999940395355" velocity="1000.0"/>
  </joint>
  <link name="SM_Fridge_Drawer_04">
    <inertial>
      <origin xyz="4.257840555510484e-05 -0.05007801949977875 -0.020410042256116867" rpy="1.5665537118911743 -1.5330750942230225 1.5746883153915405"/>
      <mass value="2.6998910903930664"/>
      <inertia ixx="0.10621564090251923" ixy="0.0" ixz="0.0" iyy="0.07615388184785843" iyz="0.0" izz="0.03804793581366539"/>
    </inertial>
  </link>
  <joint name="SM_Fridge_Shelf_joint" type="fixed">
    <origin xyz="-0.002042242791503668 -0.0010253775399178267 0.4112362563610077" rpy="0.0 0.0 0.0"/>
    <parent link="SM_Fridge_Base"/>
    <child link="SM_Fridge_Shelf"/>
  </joint>
  <link name="SM_Fridge_Shelf">
    <inertial>
      <origin xyz="0.0 0.0006809764890931547 0.0009497534483671188" rpy="3.1415927410125732 -1.570796251296997 0.0"/>
      <mass value="0.5064015984535217"/>
      <inertia ixx="0.012089570052921772" ixy="0.0" ixz="0.0" iyy="0.009105399250984192" iyz="0.0" izz="0.0029855892062187195"/>
    </inertial>
  </link>
  <joint name="SM_Fridge_Door_01_joint" type="revolute">
    <origin xyz="-0.3019707500934601 -0.27809375524520874 0.3384344279766083" rpy="0.0 0.0 -5.072174189990619e-06"/>
    <axis xyz="0.0 0.0 -1.0"/>
    <parent link="SM_Fridge_Base"/>
    <child link="SM_Fridge_Door_01"/>
    <limit effort="1000.0" lower="0.0" upper="1.5707963705062866" velocity="1000.0"/>
  </joint>
  <link name="SM_Fridge_Door_01">
    <inertial>
      <origin xyz="0.29701995849609375 0.018172448500990868 0.07750014960765839" rpy="0.0016686016460880637 -0.005027778912335634 1.5715192556381226"/>
      <mass value="29.04986572265625"/>
      <inertia ixx="4.322718143463135" ixy="0.0" ixz="0.0" iyy="3.5070509910583496" iyz="0.0" izz="0.8266739845275879"/>
    </inertial>
  </link>
  <joint name="SM_Fridge_Egg_Tray_joint" type="fixed">
    <origin xyz="0.21315930783748627 0.09950777143239975 0.22457091510295868" rpy="0.0 0.0 1.5708013772964478"/>
    <parent link="SM_Fridge_Door_01"/>
    <child link="SM_Fridge_Egg_Tray"/>
  </joint>
  <link name="SM_Fridge_Egg_Tray">
    <inertial>
      <origin xyz="-0.0010581121314316988 6.267835556128531e-11 0.012933813035488129" rpy="1.5707963705062866 -1.3965307474136353 0.0"/>
      <mass value="0.01321423426270485"/>
      <inertia ixx="3.8974900235189125e-05" ixy="0.0" ixz="0.0" iyy="2.501591734471731e-05" iyz="0.0" izz="1.396612060489133e-05"/>
    </inertial>
  </link>
  <joint name="SM_Fridge_Door_Tray_01_joint" type="fixed">
    <origin xyz="0.2972511053085327 0.10379232466220856 -0.01565246470272541" rpy="0.0 0.0 1.5708013772964478"/>
    <parent link="SM_Fridge_Door_01"/>
    <child link="SM_Fridge_Door_Tray_01"/>
  </joint>
  <link name="SM_Fridge_Door_Tray_01">
    <inertial>
      <origin xyz="0.0002351401635678485 -4.112425955327126e-10 -0.014824009500443935" rpy="1.5707963705062866 -1.5707963705062866 0.0"/>
      <mass value="0.2815645933151245"/>
      <inertia ixx="0.005742819048464298" ixy="0.0" ixz="0.0" iyy="0.005444519687443972" iyz="0.0" izz="0.00085954595124349"/>
    </inertial>
  </link>
  <joint name="SM_Fridge_Door_Tray_02_joint" type="fixed">
    <origin xyz="0.29846447706222534 0.10177694261074066 0.2238723635673523" rpy="0.0 0.0 1.5708013772964478"/>
    <parent link="SM_Fridge_Door_01"/>
    <child link="SM_Fridge_Door_Tray_02"/>
  </joint>
  <link name="SM_Fridge_Door_Tray_02">
    <inertial>
      <origin xyz="0.00023512227926403284 1.247283526462084e-10 -0.011562646366655827" rpy="1.5707963705062866 -1.5707963705062866 0.0"/>
      <mass value="0.19583383202552795"/>
      <inertia ixx="0.0038066215347498655" ixy="0.0" ixz="0.0" iyy="0.0035051496233791113" iyz="0.0" izz="0.00041756677092052996"/>
    </inertial>
  </link>
  <joint name="SM_Kitchen_Handle24_joint" type="fixed">
    <origin xyz="0.46534666419029236 -0.007986458949744701 -0.4736875891685486" rpy="0.0 0.0 1.5708041191101074"/>
    <parent link="SM_Fridge_Door_01"/>
    <child link="SM_Kitchen_Handle24"/>
  </joint>
  <link name="SM_Kitchen_Handle24">
    <inertial>
      <origin xyz="-0.01734265126287937 -4.472618456929922e-06 0.0004545578849501908" rpy="1.5707920789718628 -1.5707963705062866 0.0"/>
      <mass value="0.033401232212781906"/>
      <inertia ixx="0.00010963201930280775" ixy="0.0" ixz="0.0" iyy="0.00010809655941557139" iyz="0.0" izz="2.349011538171908e-06"/>
    </inertial>
  </link>
  <joint name="SM_Fridge_Drawer_03_joint" type="prismatic">
    <origin xyz="-0.0025136363692581654 -0.03264402598142624 -0.3561764359474182" rpy="0.0 0.0 -8.470329472543003e-22"/>
    <axis xyz="0.0 -1.0 0.0"/>
    <parent link="SM_Fridge_Base"/>
    <child link="SM_Fridge_Drawer_03"/>
    <limit effort="1000.0" lower="0.0" upper="0.3499999940395355" velocity="1000.0"/>
  </joint>
  <link name="SM_Fridge_Drawer_03">
    <inertial>
      <origin xyz="9.240576764568686e-05 -0.042103361338377 -0.01770791783928871" rpy="1.559909462928772 -1.5328044891357422 1.580829381942749"/>
      <mass value="3.598545551300049"/>
      <inertia ixx="0.14576366543769836" ixy="0.0" ixz="0.0" iyy="0.10619443655014038" iyz="0.0" izz="0.059141166508197784"/>
    </inertial>
  </link>
  <joint name="SM_Fridge_Shelf2_joint" type="fixed">
    <origin xyz="-0.002042242791503668 -0.0010253775399178267 0.498551641" rpy="0.0 0.0 0.0"/>
    <parent link="SM_Fridge_Base"/>
    <child link="SM_Fridge_Shelf2"/>
  </joint>
  <link name="SM_Fridge_Shelf2">
    <inertial>
      <origin xyz="0.0 0.0006809764890931547 0.0009497534483671188" rpy="3.1415927410125732 -1.570796251296997 0.0"/>
      <mass value="0.5064015984535217"/>
      <inertia ixx="0.012089570052921772" ixy="0.0" ixz="0.0" iyy="0.009105399250984192" iyz="0.0" izz="0.0029855892062187195"/>
    </inertial>
  </link>
  <joint name="SM_Fridge_Drawer_05_joint" type="prismatic">
    <origin xyz="4.597255974658765e-05 -0.06479736417531967 -0.7127872109413147" rpy="0.0 0.0 -8.470329472543003e-22"/>
    <axis xyz="0.0 -1.0 0.0"/>
    <parent link="SM_Fridge_Base"/>
    <child link="SM_Fridge_Drawer_05"/>
    <limit effort="1000.0" lower="0.0" upper="0.3499999940395355" velocity="1000.0"/>
  </joint>
  <link name="SM_Fridge_Drawer_05">
    <inertial>
      <origin xyz="3.5001830838155e-05 -0.014612973667681217 -0.027065975591540337" rpy="-1.5625896453857422 -1.5388201475143433 -1.579324722290039"/>
      <mass value="3.564878463745117"/>
      <inertia ixx="0.09313537180423737" ixy="0.0" ixz="0.0" iyy="0.07508959621191025" iyz="0.0" izz="0.0372905358672142"/>
    </inertial>
  </link>
  <joint name="SM_Fridge_Door_02_joint" type="revolute">
    <origin xyz="-0.30201226472854614 -0.27803272008895874 -0.5563140511512756" rpy="0.0 0.0 -5.072174189990619e-06"/>
    <axis xyz="0.0 0.0 -1.0"/>
    <parent link="SM_Fridge_Base"/>
    <child link="SM_Fridge_Door_02"/>
    <limit effort="1000.0" lower="0.0" upper="1.5707963705062866" velocity="1000.0"/>
  </joint>
  <link name="SM_Fridge_Door_02">
    <inertial>
      <origin xyz="0.29607558250427246 0.0256811510771513 0.0009382319403812289" rpy="-0.0014529336476698518 0.008796961046755314 1.5703372955322266"/>
      <mass value="23.006759643554688"/>
      <inertia ixx="1.5096763372421265" ixy="0.0" ixz="0.0" iyy="0.914759635925293" iyz="0.0" izz="0.609548807144165"/>
    </inertial>
  </link>
  <joint name="SM_Kitchen_Handle25_joint" type="fixed">
    <origin xyz="0.46538814902305603 -0.008047494105994701 0.2848682999610901" rpy="0.0 0.0 1.5708041191101074"/>
    <parent link="SM_Fridge_Door_02"/>
    <child link="SM_Kitchen_Handle25"/>
  </joint>
  <link name="SM_Kitchen_Handle25">
    <inertial>
      <origin xyz="-0.01734265126287937 -4.472618456929922e-06 0.0004545578849501908" rpy="1.5707920789718628 -1.5707963705062866 0.0"/>
      <mass value="0.033401232212781906"/>
      <inertia ixx="0.00010963201930280775" ixy="0.0" ixz="0.0" iyy="0.00010809655941557139" iyz="0.0" izz="2.349011538171908e-06"/>
    </inertial>
  </link>
  <joint name="SM_Fridge_Drawer_01_joint" type="prismatic">
    <origin xyz="-0.0022327431943267584 -0.012080064043402672 0.1102571114897728" rpy="0.0 0.0 -8.470329472543003e-22"/>
    <axis xyz="0.0 -1.0 0.0"/>
    <parent link="SM_Fridge_Base"/>
    <child link="SM_Fridge_Drawer_01"/>
    <limit effort="1000.0" lower="0.0" upper="0.3499999940395355" velocity="1000.0"/>
  </joint>
  <link name="SM_Fridge_Drawer_01">
    <inertial>
      <origin xyz="-7.24274329400032e-08 -0.04549010843038559 -0.04209451377391815" rpy="-1.5707963705062866 -1.5645804405212402 -1.5707963705062866"/>
      <mass value="4.776556491851807"/>
      <inertia ixx="0.14644287526607513" ixy="0.0" ixz="0.0" iyy="0.10802732408046722" iyz="0.0" izz="0.06149740517139435"/>
    </inertial>
  </link>
  <joint name="SM_Kitchen_09_Drawer_03_joint" type="prismatic">
    <origin xyz="7.009797096252441 -5.343707084655762 0.2253846675157547" rpy="0.0 0.0 1.570798397064209"/>
    <axis xyz="0.0 -1.0 0.0"/>
    <parent link="Root"/>
    <child link="SM_Kitchen_09_Drawer_03"/>
    <limit effort="1000.0" lower="0.0" upper="0.4000000059604645" velocity="1000.0"/>
  </joint>
  <link name="SM_Kitchen_09_Drawer_03">
    <inertial>
      <origin xyz="-2.5427215888385035e-09 -0.0572405681014061 -0.06563190370798111" rpy="0.0 -1.3127354383468628 1.5707963705062866"/>
      <mass value="10.007306098937988"/>
      <inertia ixx="0.784437358379364" ixy="0.0" ixz="0.0" iyy="0.5045651197433472" iyz="0.0" izz="0.4500564634799957"/>
    </inertial>
  </link>
  <joint name="SM_Kitchen_Handle17_joint" type="fixed">
    <origin xyz="0.0035297374706715345 -0.2515374720096588 0.1594795137643814" rpy="0.0 0.0 1.5708003044128418"/>
    <parent link="SM_Kitchen_09_Drawer_03"/>
    <child link="SM_Kitchen_Handle17"/>
  </joint>
  <link name="SM_Kitchen_Handle17">
    <inertial>
      <origin xyz="-0.01734265126287937 -4.472618456929922e-06 0.0004545578849501908" rpy="1.5707920789718628 -1.5707963705062866 0.0"/>
      <mass value="0.033401232212781906"/>
      <inertia ixx="0.00010963201930280775" ixy="0.0" ixz="0.0" iyy="0.00010809655941557139" iyz="0.0" izz="2.349011538171908e-06"/>
    </inertial>
  </link>
</robot>